2018-04-30 13:47:49,482 INFO: flask_demo start up [in /home/zj/project/daily-learning/learn-python/flask_demo/app/__init__.py:61]
2018-04-30 13:47:49,602 INFO: flask_demo start up [in /home/zj/project/daily-learning/learn-python/flask_demo/app/__init__.py:61]
2018-04-30 13:47:49,660 INFO: flask_demo start up [in /home/zj/project/daily-learning/learn-python/flask_demo/app/__init__.py:61]
2018-04-30 13:47:58,749 ERROR: Exception on /index [GET] [in /usr/local/lib/python3.5/dist-packages/flask/app.py:1560]
Traceback (most recent call last):
  File "/usr/local/lib/python3.5/dist-packages/flask/app.py", line 1982, in wsgi_app
    response = self.full_dispatch_request()
  File "/usr/local/lib/python3.5/dist-packages/flask/app.py", line 1614, in full_dispatch_request
    rv = self.handle_user_exception(e)
  File "/usr/local/lib/python3.5/dist-packages/flask/app.py", line 1517, in handle_user_exception
    reraise(exc_type, exc_value, tb)
  File "/usr/local/lib/python3.5/dist-packages/flask/_compat.py", line 33, in reraise
    raise value
  File "/usr/local/lib/python3.5/dist-packages/flask/app.py", line 1612, in full_dispatch_request
    rv = self.dispatch_request()
  File "/usr/local/lib/python3.5/dist-packages/flask/app.py", line 1598, in dispatch_request
    return self.view_functions[rule.endpoint](**req.view_args)
  File "/usr/local/lib/python3.5/dist-packages/flask_login/utils.py", line 260, in decorated_view
    return current_app.login_manager.unauthorized()
  File "/usr/local/lib/python3.5/dist-packages/flask_login/login_manager.py", line 175, in unauthorized
    redirect_url = make_login_url(login_view, next_url=request.url)
  File "/usr/local/lib/python3.5/dist-packages/flask_login/utils.py", line 112, in login_url
    base = expand_login_view(login_view)
  File "/usr/local/lib/python3.5/dist-packages/flask_login/utils.py", line 89, in expand_login_view
    return url_for(login_view)
  File "/usr/local/lib/python3.5/dist-packages/flask/helpers.py", line 333, in url_for
    return appctx.app.handle_url_build_error(error, endpoint, values)
  File "/usr/local/lib/python3.5/dist-packages/flask/app.py", line 1805, in handle_url_build_error
    reraise(exc_type, exc_value, tb)
  File "/usr/local/lib/python3.5/dist-packages/flask/_compat.py", line 33, in reraise
    raise value
  File "/usr/local/lib/python3.5/dist-packages/flask/helpers.py", line 323, in url_for
    force_external=external)
  File "/usr/local/lib/python3.5/dist-packages/werkzeug/routing.py", line 1768, in build
    raise BuildError(endpoint, values, method, self)
werkzeug.routing.BuildError: Could not build url for endpoint 'login'. Did you mean 'auth.login' instead?
2018-04-30 13:49:38,332 ERROR: Exception on /index [GET] [in /usr/local/lib/python3.5/dist-packages/flask/app.py:1560]
Traceback (most recent call last):
  File "/usr/local/lib/python3.5/dist-packages/flask/app.py", line 1982, in wsgi_app
    response = self.full_dispatch_request()
  File "/usr/local/lib/python3.5/dist-packages/flask/app.py", line 1614, in full_dispatch_request
    rv = self.handle_user_exception(e)
  File "/usr/local/lib/python3.5/dist-packages/flask/app.py", line 1517, in handle_user_exception
    reraise(exc_type, exc_value, tb)
  File "/usr/local/lib/python3.5/dist-packages/flask/_compat.py", line 33, in reraise
    raise value
  File "/usr/local/lib/python3.5/dist-packages/flask/app.py", line 1612, in full_dispatch_request
    rv = self.dispatch_request()
  File "/usr/local/lib/python3.5/dist-packages/flask/app.py", line 1598, in dispatch_request
    return self.view_functions[rule.endpoint](**req.view_args)
  File "/usr/local/lib/python3.5/dist-packages/flask_login/utils.py", line 260, in decorated_view
    return current_app.login_manager.unauthorized()
  File "/usr/local/lib/python3.5/dist-packages/flask_login/login_manager.py", line 175, in unauthorized
    redirect_url = make_login_url(login_view, next_url=request.url)
  File "/usr/local/lib/python3.5/dist-packages/flask_login/utils.py", line 112, in login_url
    base = expand_login_view(login_view)
  File "/usr/local/lib/python3.5/dist-packages/flask_login/utils.py", line 89, in expand_login_view
    return url_for(login_view)
  File "/usr/local/lib/python3.5/dist-packages/flask/helpers.py", line 333, in url_for
    return appctx.app.handle_url_build_error(error, endpoint, values)
  File "/usr/local/lib/python3.5/dist-packages/flask/app.py", line 1805, in handle_url_build_error
    reraise(exc_type, exc_value, tb)
  File "/usr/local/lib/python3.5/dist-packages/flask/_compat.py", line 33, in reraise
    raise value
  File "/usr/local/lib/python3.5/dist-packages/flask/helpers.py", line 323, in url_for
    force_external=external)
  File "/usr/local/lib/python3.5/dist-packages/werkzeug/routing.py", line 1768, in build
    raise BuildError(endpoint, values, method, self)
werkzeug.routing.BuildError: Could not build url for endpoint 'login'. Did you mean 'auth.login' instead?
2018-04-30 13:49:51,674 ERROR: Exception on /index [GET] [in /usr/local/lib/python3.5/dist-packages/flask/app.py:1560]
Traceback (most recent call last):
  File "/usr/local/lib/python3.5/dist-packages/flask/app.py", line 1982, in wsgi_app
    response = self.full_dispatch_request()
  File "/usr/local/lib/python3.5/dist-packages/flask/app.py", line 1614, in full_dispatch_request
    rv = self.handle_user_exception(e)
  File "/usr/local/lib/python3.5/dist-packages/flask/app.py", line 1517, in handle_user_exception
    reraise(exc_type, exc_value, tb)
  File "/usr/local/lib/python3.5/dist-packages/flask/_compat.py", line 33, in reraise
    raise value
  File "/usr/local/lib/python3.5/dist-packages/flask/app.py", line 1612, in full_dispatch_request
    rv = self.dispatch_request()
  File "/usr/local/lib/python3.5/dist-packages/flask/app.py", line 1598, in dispatch_request
    return self.view_functions[rule.endpoint](**req.view_args)
  File "/usr/local/lib/python3.5/dist-packages/flask_login/utils.py", line 260, in decorated_view
    return current_app.login_manager.unauthorized()
  File "/usr/local/lib/python3.5/dist-packages/flask_login/login_manager.py", line 175, in unauthorized
    redirect_url = make_login_url(login_view, next_url=request.url)
  File "/usr/local/lib/python3.5/dist-packages/flask_login/utils.py", line 112, in login_url
    base = expand_login_view(login_view)
  File "/usr/local/lib/python3.5/dist-packages/flask_login/utils.py", line 89, in expand_login_view
    return url_for(login_view)
  File "/usr/local/lib/python3.5/dist-packages/flask/helpers.py", line 333, in url_for
    return appctx.app.handle_url_build_error(error, endpoint, values)
  File "/usr/local/lib/python3.5/dist-packages/flask/app.py", line 1805, in handle_url_build_error
    reraise(exc_type, exc_value, tb)
  File "/usr/local/lib/python3.5/dist-packages/flask/_compat.py", line 33, in reraise
    raise value
  File "/usr/local/lib/python3.5/dist-packages/flask/helpers.py", line 323, in url_for
    force_external=external)
  File "/usr/local/lib/python3.5/dist-packages/werkzeug/routing.py", line 1768, in build
    raise BuildError(endpoint, values, method, self)
werkzeug.routing.BuildError: Could not build url for endpoint 'login'. Did you mean 'auth.login' instead?
2018-04-30 13:51:06,601 ERROR: Exception on / [GET] [in /usr/local/lib/python3.5/dist-packages/flask/app.py:1560]
Traceback (most recent call last):
  File "/usr/local/lib/python3.5/dist-packages/flask/app.py", line 1982, in wsgi_app
    response = self.full_dispatch_request()
  File "/usr/local/lib/python3.5/dist-packages/flask/app.py", line 1614, in full_dispatch_request
    rv = self.handle_user_exception(e)
  File "/usr/local/lib/python3.5/dist-packages/flask/app.py", line 1517, in handle_user_exception
    reraise(exc_type, exc_value, tb)
  File "/usr/local/lib/python3.5/dist-packages/flask/_compat.py", line 33, in reraise
    raise value
  File "/usr/local/lib/python3.5/dist-packages/flask/app.py", line 1612, in full_dispatch_request
    rv = self.dispatch_request()
  File "/usr/local/lib/python3.5/dist-packages/flask/app.py", line 1598, in dispatch_request
    return self.view_functions[rule.endpoint](**req.view_args)
  File "/usr/local/lib/python3.5/dist-packages/flask_login/utils.py", line 260, in decorated_view
    return current_app.login_manager.unauthorized()
  File "/usr/local/lib/python3.5/dist-packages/flask_login/login_manager.py", line 175, in unauthorized
    redirect_url = make_login_url(login_view, next_url=request.url)
  File "/usr/local/lib/python3.5/dist-packages/flask_login/utils.py", line 112, in login_url
    base = expand_login_view(login_view)
  File "/usr/local/lib/python3.5/dist-packages/flask_login/utils.py", line 89, in expand_login_view
    return url_for(login_view)
  File "/usr/local/lib/python3.5/dist-packages/flask/helpers.py", line 333, in url_for
    return appctx.app.handle_url_build_error(error, endpoint, values)
  File "/usr/local/lib/python3.5/dist-packages/flask/app.py", line 1805, in handle_url_build_error
    reraise(exc_type, exc_value, tb)
  File "/usr/local/lib/python3.5/dist-packages/flask/_compat.py", line 33, in reraise
    raise value
  File "/usr/local/lib/python3.5/dist-packages/flask/helpers.py", line 323, in url_for
    force_external=external)
  File "/usr/local/lib/python3.5/dist-packages/werkzeug/routing.py", line 1768, in build
    raise BuildError(endpoint, values, method, self)
werkzeug.routing.BuildError: Could not build url for endpoint 'login'. Did you mean 'auth.login' instead?
